2021-04-15 18:37:12,569 INFO: Microblog startup [in /home/kavvadias/Projects/flask-mega/app/__init__.py:44]
2021-04-15 18:37:41,241 ERROR: Exception on /edit_profile [POST] [in /home/kavvadias/Projects/flask-mega/venv/lib/python3.9/site-packages/flask/app.py:1891]
Traceback (most recent call last):
  File "/home/kavvadias/Projects/flask-mega/venv/lib/python3.9/site-packages/sqlalchemy/engine/base.py", line 1705, in _execute_context
    self.dialect.do_execute(
  File "/home/kavvadias/Projects/flask-mega/venv/lib/python3.9/site-packages/sqlalchemy/engine/default.py", line 692, in do_execute
    cursor.execute(statement, parameters)
sqlite3.IntegrityError: UNIQUE constraint failed: user.username

The above exception was the direct cause of the following exception:

Traceback (most recent call last):
  File "/home/kavvadias/Projects/flask-mega/venv/lib/python3.9/site-packages/flask/app.py", line 2447, in wsgi_app
    response = self.full_dispatch_request()
  File "/home/kavvadias/Projects/flask-mega/venv/lib/python3.9/site-packages/flask/app.py", line 1952, in full_dispatch_request
    rv = self.handle_user_exception(e)
  File "/home/kavvadias/Projects/flask-mega/venv/lib/python3.9/site-packages/flask/app.py", line 1821, in handle_user_exception
    reraise(exc_type, exc_value, tb)
  File "/home/kavvadias/Projects/flask-mega/venv/lib/python3.9/site-packages/flask/_compat.py", line 39, in reraise
    raise value
  File "/home/kavvadias/Projects/flask-mega/venv/lib/python3.9/site-packages/flask/app.py", line 1950, in full_dispatch_request
    rv = self.dispatch_request()
  File "/home/kavvadias/Projects/flask-mega/venv/lib/python3.9/site-packages/flask/app.py", line 1936, in dispatch_request
    return self.view_functions[rule.endpoint](**req.view_args)
  File "/home/kavvadias/Projects/flask-mega/venv/lib/python3.9/site-packages/flask_login/utils.py", line 272, in decorated_view
    return func(*args, **kwargs)
  File "/home/kavvadias/Projects/flask-mega/app/routes.py", line 91, in edit_profile
    db.session.commit()
  File "<string>", line 2, in commit
  File "/home/kavvadias/Projects/flask-mega/venv/lib/python3.9/site-packages/sqlalchemy/orm/session.py", line 1423, in commit
    self._transaction.commit(_to_root=self.future)
  File "/home/kavvadias/Projects/flask-mega/venv/lib/python3.9/site-packages/sqlalchemy/orm/session.py", line 829, in commit
    self._prepare_impl()
  File "/home/kavvadias/Projects/flask-mega/venv/lib/python3.9/site-packages/sqlalchemy/orm/session.py", line 808, in _prepare_impl
    self.session.flush()
  File "/home/kavvadias/Projects/flask-mega/venv/lib/python3.9/site-packages/sqlalchemy/orm/session.py", line 3241, in flush
    self._flush(objects)
  File "/home/kavvadias/Projects/flask-mega/venv/lib/python3.9/site-packages/sqlalchemy/orm/session.py", line 3381, in _flush
    transaction.rollback(_capture_exception=True)
  File "/home/kavvadias/Projects/flask-mega/venv/lib/python3.9/site-packages/sqlalchemy/util/langhelpers.py", line 70, in __exit__
    compat.raise_(
  File "/home/kavvadias/Projects/flask-mega/venv/lib/python3.9/site-packages/sqlalchemy/util/compat.py", line 211, in raise_
    raise exception
  File "/home/kavvadias/Projects/flask-mega/venv/lib/python3.9/site-packages/sqlalchemy/orm/session.py", line 3341, in _flush
    flush_context.execute()
  File "/home/kavvadias/Projects/flask-mega/venv/lib/python3.9/site-packages/sqlalchemy/orm/unitofwork.py", line 453, in execute
    rec.execute(self)
  File "/home/kavvadias/Projects/flask-mega/venv/lib/python3.9/site-packages/sqlalchemy/orm/unitofwork.py", line 627, in execute
    util.preloaded.orm_persistence.save_obj(
  File "/home/kavvadias/Projects/flask-mega/venv/lib/python3.9/site-packages/sqlalchemy/orm/persistence.py", line 234, in save_obj
    _emit_update_statements(
  File "/home/kavvadias/Projects/flask-mega/venv/lib/python3.9/site-packages/sqlalchemy/orm/persistence.py", line 998, in _emit_update_statements
    c = connection._execute_20(
  File "/home/kavvadias/Projects/flask-mega/venv/lib/python3.9/site-packages/sqlalchemy/engine/base.py", line 1520, in _execute_20
    return meth(self, args_10style, kwargs_10style, execution_options)
  File "/home/kavvadias/Projects/flask-mega/venv/lib/python3.9/site-packages/sqlalchemy/sql/elements.py", line 313, in _execute_on_connection
    return connection._execute_clauseelement(
  File "/home/kavvadias/Projects/flask-mega/venv/lib/python3.9/site-packages/sqlalchemy/engine/base.py", line 1389, in _execute_clauseelement
    ret = self._execute_context(
  File "/home/kavvadias/Projects/flask-mega/venv/lib/python3.9/site-packages/sqlalchemy/engine/base.py", line 1748, in _execute_context
    self._handle_dbapi_exception(
  File "/home/kavvadias/Projects/flask-mega/venv/lib/python3.9/site-packages/sqlalchemy/engine/base.py", line 1929, in _handle_dbapi_exception
    util.raise_(
  File "/home/kavvadias/Projects/flask-mega/venv/lib/python3.9/site-packages/sqlalchemy/util/compat.py", line 211, in raise_
    raise exception
  File "/home/kavvadias/Projects/flask-mega/venv/lib/python3.9/site-packages/sqlalchemy/engine/base.py", line 1705, in _execute_context
    self.dialect.do_execute(
  File "/home/kavvadias/Projects/flask-mega/venv/lib/python3.9/site-packages/sqlalchemy/engine/default.py", line 692, in do_execute
    cursor.execute(statement, parameters)
sqlalchemy.exc.IntegrityError: (sqlite3.IntegrityError) UNIQUE constraint failed: user.username
[SQL: UPDATE user SET username=?, about_me=? WHERE user.id = ?]
[parameters: ('susan', 'De kserw ti na grapsw alla xristos anesth kai agios o theos, panagia konta mas!\r\n', 2)]
(Background on this error at: http://sqlalche.me/e/14/gkpj)
2021-04-15 18:44:57,194 INFO: Microblog startup [in /home/kavvadias/Projects/flask-mega/app/__init__.py:44]
2021-04-15 19:12:46,907 INFO: Microblog startup [in /home/kavvadias/Projects/flask-mega/app/__init__.py:44]
2021-04-15 19:12:58,895 INFO: Microblog startup [in /home/kavvadias/Projects/flask-mega/app/__init__.py:44]
2021-04-15 19:50:49,490 INFO: Microblog startup [in /home/kavvadias/Projects/flask-mega/app/__init__.py:44]
2021-04-15 19:53:09,452 INFO: Microblog startup [in /home/kavvadias/Projects/flask-mega/app/__init__.py:44]
2021-04-15 20:17:21,980 INFO: Microblog startup [in /home/kavvadias/Projects/flask-mega/app/__init__.py:44]
2021-04-15 20:17:27,062 INFO: Microblog startup [in /home/kavvadias/Projects/flask-mega/app/__init__.py:44]
2021-04-15 20:17:47,097 ERROR: Exception on /follow/susan [POST] [in /home/kavvadias/Projects/flask-mega/venv/lib/python3.9/site-packages/flask/app.py:1891]
Traceback (most recent call last):
  File "/home/kavvadias/Projects/flask-mega/venv/lib/python3.9/site-packages/flask/app.py", line 2447, in wsgi_app
    response = self.full_dispatch_request()
  File "/home/kavvadias/Projects/flask-mega/venv/lib/python3.9/site-packages/flask/app.py", line 1952, in full_dispatch_request
    rv = self.handle_user_exception(e)
  File "/home/kavvadias/Projects/flask-mega/venv/lib/python3.9/site-packages/flask/app.py", line 1821, in handle_user_exception
    reraise(exc_type, exc_value, tb)
  File "/home/kavvadias/Projects/flask-mega/venv/lib/python3.9/site-packages/flask/_compat.py", line 39, in reraise
    raise value
  File "/home/kavvadias/Projects/flask-mega/venv/lib/python3.9/site-packages/flask/app.py", line 1950, in full_dispatch_request
    rv = self.dispatch_request()
  File "/home/kavvadias/Projects/flask-mega/venv/lib/python3.9/site-packages/flask/app.py", line 1936, in dispatch_request
    return self.view_functions[rule.endpoint](**req.view_args)
  File "/home/kavvadias/Projects/flask-mega/venv/lib/python3.9/site-packages/flask_login/utils.py", line 272, in decorated_view
    return func(*args, **kwargs)
  File "/home/kavvadias/Projects/flask-mega/app/routes.py", line 107, in follow
    if user in None:
TypeError: argument of type 'NoneType' is not iterable
2021-04-15 20:18:19,629 INFO: Microblog startup [in /home/kavvadias/Projects/flask-mega/app/__init__.py:44]
2021-04-15 20:52:15,275 INFO: Microblog startup [in /home/kavvadias/Projects/flask-mega/app/__init__.py:44]
2021-04-15 21:09:30,329 INFO: Microblog startup [in /home/kavvadias/Projects/flask-mega/app/__init__.py:44]
2021-04-15 21:09:46,278 ERROR: Exception on /index [GET] [in /home/kavvadias/Projects/flask-mega/venv/lib/python3.9/site-packages/flask/app.py:1891]
Traceback (most recent call last):
  File "/home/kavvadias/Projects/flask-mega/venv/lib/python3.9/site-packages/flask/app.py", line 2447, in wsgi_app
    response = self.full_dispatch_request()
  File "/home/kavvadias/Projects/flask-mega/venv/lib/python3.9/site-packages/flask/app.py", line 1952, in full_dispatch_request
    rv = self.handle_user_exception(e)
  File "/home/kavvadias/Projects/flask-mega/venv/lib/python3.9/site-packages/flask/app.py", line 1821, in handle_user_exception
    reraise(exc_type, exc_value, tb)
  File "/home/kavvadias/Projects/flask-mega/venv/lib/python3.9/site-packages/flask/_compat.py", line 39, in reraise
    raise value
  File "/home/kavvadias/Projects/flask-mega/venv/lib/python3.9/site-packages/flask/app.py", line 1950, in full_dispatch_request
    rv = self.dispatch_request()
  File "/home/kavvadias/Projects/flask-mega/venv/lib/python3.9/site-packages/flask/app.py", line 1936, in dispatch_request
    return self.view_functions[rule.endpoint](**req.view_args)
  File "/home/kavvadias/Projects/flask-mega/venv/lib/python3.9/site-packages/flask_login/utils.py", line 272, in decorated_view
    return func(*args, **kwargs)
  File "/home/kavvadias/Projects/flask-mega/app/routes.py", line 30, in index
    page, app.config['POST_PER_PAGE'], False)
KeyError: 'POST_PER_PAGE'
