2021-04-15 21:10:23,929 ERROR: Exception on /index [GET] [in /home/kavvadias/Projects/flask-mega/venv/lib/python3.9/site-packages/flask/app.py:1891]
Traceback (most recent call last):
  File "/home/kavvadias/Projects/flask-mega/venv/lib/python3.9/site-packages/flask/app.py", line 2447, in wsgi_app
    response = self.full_dispatch_request()
  File "/home/kavvadias/Projects/flask-mega/venv/lib/python3.9/site-packages/flask/app.py", line 1952, in full_dispatch_request
    rv = self.handle_user_exception(e)
  File "/home/kavvadias/Projects/flask-mega/venv/lib/python3.9/site-packages/flask/app.py", line 1821, in handle_user_exception
    reraise(exc_type, exc_value, tb)
  File "/home/kavvadias/Projects/flask-mega/venv/lib/python3.9/site-packages/flask/_compat.py", line 39, in reraise
    raise value
  File "/home/kavvadias/Projects/flask-mega/venv/lib/python3.9/site-packages/flask/app.py", line 1950, in full_dispatch_request
    rv = self.dispatch_request()
  File "/home/kavvadias/Projects/flask-mega/venv/lib/python3.9/site-packages/flask/app.py", line 1936, in dispatch_request
    return self.view_functions[rule.endpoint](**req.view_args)
  File "/home/kavvadias/Projects/flask-mega/venv/lib/python3.9/site-packages/flask_login/utils.py", line 272, in decorated_view
    return func(*args, **kwargs)
  File "/home/kavvadias/Projects/flask-mega/app/routes.py", line 30, in index
    page, app.config['POSTS_PER_PAGE'], False)
KeyError: 'POST_PER_PAGE'
2021-04-15 21:10:24,985 ERROR: Exception on /index [GET] [in /home/kavvadias/Projects/flask-mega/venv/lib/python3.9/site-packages/flask/app.py:1891]
Traceback (most recent call last):
  File "/home/kavvadias/Projects/flask-mega/venv/lib/python3.9/site-packages/flask/app.py", line 2447, in wsgi_app
    response = self.full_dispatch_request()
  File "/home/kavvadias/Projects/flask-mega/venv/lib/python3.9/site-packages/flask/app.py", line 1952, in full_dispatch_request
    rv = self.handle_user_exception(e)
  File "/home/kavvadias/Projects/flask-mega/venv/lib/python3.9/site-packages/flask/app.py", line 1821, in handle_user_exception
    reraise(exc_type, exc_value, tb)
  File "/home/kavvadias/Projects/flask-mega/venv/lib/python3.9/site-packages/flask/_compat.py", line 39, in reraise
    raise value
  File "/home/kavvadias/Projects/flask-mega/venv/lib/python3.9/site-packages/flask/app.py", line 1950, in full_dispatch_request
    rv = self.dispatch_request()
  File "/home/kavvadias/Projects/flask-mega/venv/lib/python3.9/site-packages/flask/app.py", line 1936, in dispatch_request
    return self.view_functions[rule.endpoint](**req.view_args)
  File "/home/kavvadias/Projects/flask-mega/venv/lib/python3.9/site-packages/flask_login/utils.py", line 272, in decorated_view
    return func(*args, **kwargs)
  File "/home/kavvadias/Projects/flask-mega/app/routes.py", line 30, in index
    page, app.config['POSTS_PER_PAGE'], False)
KeyError: 'POST_PER_PAGE'
2021-04-15 21:10:31,084 INFO: Microblog startup [in /home/kavvadias/Projects/flask-mega/app/__init__.py:44]
2021-04-15 21:30:48,099 INFO: Microblog startup [in /home/kavvadias/Projects/flask-mega/app/__init__.py:44]
2021-04-15 21:31:44,658 INFO: Microblog startup [in /home/kavvadias/Projects/flask-mega/app/__init__.py:44]
2021-04-15 21:43:54,110 INFO: Microblog startup [in /home/kavvadias/Projects/flask-mega/app/__init__.py:44]
2021-04-15 21:45:10,984 INFO: Microblog startup [in /home/kavvadias/Projects/flask-mega/app/__init__.py:44]
2021-04-15 21:46:12,588 INFO: Microblog startup [in /home/kavvadias/Projects/flask-mega/app/__init__.py:44]
2021-04-15 21:47:00,643 INFO: Microblog startup [in /home/kavvadias/Projects/flask-mega/app/__init__.py:44]
2021-04-15 21:47:59,124 INFO: Microblog startup [in /home/kavvadias/Projects/flask-mega/app/__init__.py:44]
2021-04-15 21:48:07,499 ERROR: Exception on /index [GET] [in /home/kavvadias/Projects/flask-mega/venv/lib/python3.9/site-packages/flask/app.py:1891]
Traceback (most recent call last):
  File "/home/kavvadias/Projects/flask-mega/venv/lib/python3.9/site-packages/flask/app.py", line 2447, in wsgi_app
    response = self.full_dispatch_request()
  File "/home/kavvadias/Projects/flask-mega/venv/lib/python3.9/site-packages/flask/app.py", line 1952, in full_dispatch_request
    rv = self.handle_user_exception(e)
  File "/home/kavvadias/Projects/flask-mega/venv/lib/python3.9/site-packages/flask/app.py", line 1821, in handle_user_exception
    reraise(exc_type, exc_value, tb)
  File "/home/kavvadias/Projects/flask-mega/venv/lib/python3.9/site-packages/flask/_compat.py", line 39, in reraise
    raise value
  File "/home/kavvadias/Projects/flask-mega/venv/lib/python3.9/site-packages/flask/app.py", line 1950, in full_dispatch_request
    rv = self.dispatch_request()
  File "/home/kavvadias/Projects/flask-mega/venv/lib/python3.9/site-packages/flask/app.py", line 1936, in dispatch_request
    return self.view_functions[rule.endpoint](**req.view_args)
  File "/home/kavvadias/Projects/flask-mega/venv/lib/python3.9/site-packages/flask_login/utils.py", line 272, in decorated_view
    return func(*args, **kwargs)
  File "/home/kavvadias/Projects/flask-mega/app/routes.py", line 33, in index
    prev_url = url_for('index', page=page.prev_num) \
AttributeError: 'int' object has no attribute 'prev_num'
2021-04-15 21:49:03,046 INFO: Microblog startup [in /home/kavvadias/Projects/flask-mega/app/__init__.py:44]
2021-04-15 21:49:05,080 ERROR: Exception on /index [GET] [in /home/kavvadias/Projects/flask-mega/venv/lib/python3.9/site-packages/flask/app.py:1891]
Traceback (most recent call last):
  File "/home/kavvadias/Projects/flask-mega/venv/lib/python3.9/site-packages/flask/app.py", line 2447, in wsgi_app
    response = self.full_dispatch_request()
  File "/home/kavvadias/Projects/flask-mega/venv/lib/python3.9/site-packages/flask/app.py", line 1952, in full_dispatch_request
    rv = self.handle_user_exception(e)
  File "/home/kavvadias/Projects/flask-mega/venv/lib/python3.9/site-packages/flask/app.py", line 1821, in handle_user_exception
    reraise(exc_type, exc_value, tb)
  File "/home/kavvadias/Projects/flask-mega/venv/lib/python3.9/site-packages/flask/_compat.py", line 39, in reraise
    raise value
  File "/home/kavvadias/Projects/flask-mega/venv/lib/python3.9/site-packages/flask/app.py", line 1950, in full_dispatch_request
    rv = self.dispatch_request()
  File "/home/kavvadias/Projects/flask-mega/venv/lib/python3.9/site-packages/flask/app.py", line 1936, in dispatch_request
    return self.view_functions[rule.endpoint](**req.view_args)
  File "/home/kavvadias/Projects/flask-mega/venv/lib/python3.9/site-packages/flask_login/utils.py", line 272, in decorated_view
    return func(*args, **kwargs)
  File "/home/kavvadias/Projects/flask-mega/app/routes.py", line 33, in index
    prev_url = url_for('index', page=page.prev_num) \
AttributeError: 'int' object has no attribute 'prev_num'
2021-04-15 21:49:08,676 ERROR: Exception on /index [GET] [in /home/kavvadias/Projects/flask-mega/venv/lib/python3.9/site-packages/flask/app.py:1891]
Traceback (most recent call last):
  File "/home/kavvadias/Projects/flask-mega/venv/lib/python3.9/site-packages/flask/app.py", line 2447, in wsgi_app
    response = self.full_dispatch_request()
  File "/home/kavvadias/Projects/flask-mega/venv/lib/python3.9/site-packages/flask/app.py", line 1952, in full_dispatch_request
    rv = self.handle_user_exception(e)
  File "/home/kavvadias/Projects/flask-mega/venv/lib/python3.9/site-packages/flask/app.py", line 1821, in handle_user_exception
    reraise(exc_type, exc_value, tb)
  File "/home/kavvadias/Projects/flask-mega/venv/lib/python3.9/site-packages/flask/_compat.py", line 39, in reraise
    raise value
  File "/home/kavvadias/Projects/flask-mega/venv/lib/python3.9/site-packages/flask/app.py", line 1950, in full_dispatch_request
    rv = self.dispatch_request()
  File "/home/kavvadias/Projects/flask-mega/venv/lib/python3.9/site-packages/flask/app.py", line 1936, in dispatch_request
    return self.view_functions[rule.endpoint](**req.view_args)
  File "/home/kavvadias/Projects/flask-mega/venv/lib/python3.9/site-packages/flask_login/utils.py", line 272, in decorated_view
    return func(*args, **kwargs)
  File "/home/kavvadias/Projects/flask-mega/app/routes.py", line 33, in index
    prev_url = url_for('index', page=page.prev_num) \
AttributeError: 'int' object has no attribute 'prev_num'
2021-04-15 21:49:41,721 INFO: Microblog startup [in /home/kavvadias/Projects/flask-mega/app/__init__.py:44]
